[2025-02-08T07:58:33.184+0000] {local_task_job_runner.py:123} INFO - ::group::Pre task execution logs
[2025-02-08T07:58:33.433+0000] {taskinstance.py:2613} INFO - Dependencies all met for dep_context=non-requeueable deps ti=<TaskInstance: Incident_Report_Generation.generar_reporte manual__2025-02-08T07:57:50.293591+00:00 [queued]>
[2025-02-08T07:58:33.455+0000] {taskinstance.py:2613} INFO - Dependencies all met for dep_context=requeueable deps ti=<TaskInstance: Incident_Report_Generation.generar_reporte manual__2025-02-08T07:57:50.293591+00:00 [queued]>
[2025-02-08T07:58:33.458+0000] {taskinstance.py:2866} INFO - Starting attempt 1 of 2
[2025-02-08T07:58:33.496+0000] {taskinstance.py:2889} INFO - Executing <Task(PythonOperator): generar_reporte> on 2025-02-08 07:57:50.293591+00:00
[2025-02-08T07:58:33.535+0000] {warnings.py:112} WARNING - /home/***/.local/lib/python3.12/site-packages/***/task/task_runner/standard_task_runner.py:70: DeprecationWarning: This process (pid=5257) is multi-threaded, use of fork() may lead to deadlocks in the child.
  pid = os.fork()

[2025-02-08T07:58:33.533+0000] {standard_task_runner.py:104} INFO - Running: ['***', 'tasks', 'run', 'Incident_Report_Generation', 'generar_reporte', 'manual__2025-02-08T07:57:50.293591+00:00', '--job-id', '249', '--raw', '--subdir', 'DAGS_FOLDER/Incident_Report_Generation.py', '--cfg-path', '/tmp/tmpi6t5wof1']
[2025-02-08T07:58:33.536+0000] {standard_task_runner.py:72} INFO - Started process 5259 to run task
[2025-02-08T07:58:33.537+0000] {standard_task_runner.py:105} INFO - Job 249: Subtask generar_reporte
[2025-02-08T07:58:33.627+0000] {task_command.py:467} INFO - Running <TaskInstance: Incident_Report_Generation.generar_reporte manual__2025-02-08T07:57:50.293591+00:00 [running]> on host 0b0ecc2e9e80
[2025-02-08T07:58:33.816+0000] {taskinstance.py:3132} INFO - Exporting env vars: AIRFLOW_CTX_DAG_OWNER='***' AIRFLOW_CTX_DAG_ID='Incident_Report_Generation' AIRFLOW_CTX_TASK_ID='generar_reporte' AIRFLOW_CTX_EXECUTION_DATE='2025-02-08T07:57:50.293591+00:00' AIRFLOW_CTX_TRY_NUMBER='1' AIRFLOW_CTX_DAG_RUN_ID='manual__2025-02-08T07:57:50.293591+00:00'
[2025-02-08T07:58:33.817+0000] {logging_mixin.py:190} INFO - Task instance is in running state
[2025-02-08T07:58:33.820+0000] {logging_mixin.py:190} INFO -  Previous state of the Task instance: queued
[2025-02-08T07:58:33.821+0000] {logging_mixin.py:190} INFO - Current task name:generar_reporte state:running start_date:2025-02-08 07:58:33.434253+00:00
[2025-02-08T07:58:33.821+0000] {logging_mixin.py:190} INFO - Dag name:Incident_Report_Generation and current dag run status:running
[2025-02-08T07:58:33.822+0000] {taskinstance.py:731} INFO - ::endgroup::
[2025-02-08T07:58:33.882+0000] {base.py:84} INFO - Retrieving connection 'mysql_default1'
[2025-02-08T07:58:34.141+0000] {taskinstance.py:3311} ERROR - Task failed with exception
Traceback (most recent call last):
  File "/home/airflow/.local/lib/python3.12/site-packages/airflow/models/taskinstance.py", line 767, in _execute_task
    result = _execute_callable(context=context, **execute_callable_kwargs)
             ^^^^^^^^^^^^^^^^^^^^^^^^^^^^^^^^^^^^^^^^^^^^^^^^^^^^^^^^^^^^^
  File "/home/airflow/.local/lib/python3.12/site-packages/airflow/models/taskinstance.py", line 733, in _execute_callable
    return ExecutionCallableRunner(
           ^^^^^^^^^^^^^^^^^^^^^^^^
  File "/home/airflow/.local/lib/python3.12/site-packages/airflow/utils/operator_helpers.py", line 252, in run
    return self.func(*args, **kwargs)
           ^^^^^^^^^^^^^^^^^^^^^^^^^^
  File "/home/airflow/.local/lib/python3.12/site-packages/airflow/models/baseoperator.py", line 422, in wrapper
    return func(self, *args, **kwargs)
           ^^^^^^^^^^^^^^^^^^^^^^^^^^^
  File "/home/airflow/.local/lib/python3.12/site-packages/airflow/operators/python.py", line 238, in execute
    return_value = self.execute_callable()
                   ^^^^^^^^^^^^^^^^^^^^^^^
  File "/home/airflow/.local/lib/python3.12/site-packages/airflow/operators/python.py", line 256, in execute_callable
    return runner.run(*self.op_args, **self.op_kwargs)
           ^^^^^^^^^^^^^^^^^^^^^^^^^^^^^^^^^^^^^^^^^^^
  File "/home/airflow/.local/lib/python3.12/site-packages/airflow/utils/operator_helpers.py", line 252, in run
    return self.func(*args, **kwargs)
           ^^^^^^^^^^^^^^^^^^^^^^^^^^
  File "/opt/airflow/dags/Incident_Report_Generation.py", line 187, in generar_reporte
    cursor.execute("SELECT switch_name, cliente_name FROM switches_y_clientes")
  File "/home/airflow/.local/lib/python3.12/site-packages/MySQLdb/cursors.py", line 179, in execute
    res = self._query(mogrified_query)
          ^^^^^^^^^^^^^^^^^^^^^^^^^^^^
  File "/home/airflow/.local/lib/python3.12/site-packages/MySQLdb/cursors.py", line 330, in _query
    db.query(q)
  File "/home/airflow/.local/lib/python3.12/site-packages/MySQLdb/connections.py", line 265, in query
    _mysql.connection.query(self, query)
MySQLdb.OperationalError: (1054, "Unknown column 'cliente_name' in 'field list'")
[2025-02-08T07:58:34.180+0000] {logging_mixin.py:190} INFO - Task instance in failure state
[2025-02-08T07:58:34.181+0000] {logging_mixin.py:190} INFO - Task start:2025-02-08 07:58:33.434253+00:00 end:2025-02-08 07:58:34.179821+00:00 duration:0.745568
[2025-02-08T07:58:34.182+0000] {logging_mixin.py:190} INFO - Task:<Task(PythonOperator): generar_reporte> dag:<DAG: Incident_Report_Generation> dagrun:<DagRun Incident_Report_Generation @ 2025-02-08 07:57:50.293591+00:00: manual__2025-02-08T07:57:50.293591+00:00, state:running, queued_at: 2025-02-08 07:57:51.124337+00:00. externally triggered: True>
[2025-02-08T07:58:34.183+0000] {logging_mixin.py:190} INFO - Failure caused by (1054, "Unknown column 'cliente_name' in 'field list'")
[2025-02-08T07:58:34.184+0000] {taskinstance.py:1225} INFO - Marking task as UP_FOR_RETRY. dag_id=Incident_Report_Generation, task_id=generar_reporte, run_id=manual__2025-02-08T07:57:50.293591+00:00, execution_date=20250208T075750, start_date=20250208T075833, end_date=20250208T075834
[2025-02-08T07:58:34.215+0000] {taskinstance.py:340} INFO - ::group::Post task execution logs
[2025-02-08T07:58:34.216+0000] {standard_task_runner.py:124} ERROR - Failed to execute job 249 for task generar_reporte ((1054, "Unknown column 'cliente_name' in 'field list'"); 5259)
Traceback (most recent call last):
  File "/home/airflow/.local/lib/python3.12/site-packages/airflow/task/task_runner/standard_task_runner.py", line 117, in _start_by_fork
    ret = args.func(args, dag=self.dag)
          ^^^^^^^^^^^^^^^^^^^^^^^^^^^^^
  File "/home/airflow/.local/lib/python3.12/site-packages/airflow/cli/cli_config.py", line 49, in command
    return func(*args, **kwargs)
           ^^^^^^^^^^^^^^^^^^^^^
  File "/home/airflow/.local/lib/python3.12/site-packages/airflow/utils/cli.py", line 116, in wrapper
    return f(*args, **kwargs)
           ^^^^^^^^^^^^^^^^^^
  File "/home/airflow/.local/lib/python3.12/site-packages/airflow/cli/commands/task_command.py", line 483, in task_run
    task_return_code = _run_task_by_selected_method(args, _dag, ti)
                       ^^^^^^^^^^^^^^^^^^^^^^^^^^^^^^^^^^^^^^^^^^^^
  File "/home/airflow/.local/lib/python3.12/site-packages/airflow/cli/commands/task_command.py", line 256, in _run_task_by_selected_method
    return _run_raw_task(args, ti)
           ^^^^^^^^^^^^^^^^^^^^^^^
  File "/home/airflow/.local/lib/python3.12/site-packages/airflow/cli/commands/task_command.py", line 341, in _run_raw_task
    return ti._run_raw_task(
           ^^^^^^^^^^^^^^^^^
  File "/home/airflow/.local/lib/python3.12/site-packages/airflow/utils/session.py", line 97, in wrapper
    return func(*args, session=session, **kwargs)
           ^^^^^^^^^^^^^^^^^^^^^^^^^^^^^^^^^^^^^^
  File "/home/airflow/.local/lib/python3.12/site-packages/airflow/models/taskinstance.py", line 3005, in _run_raw_task
    return _run_raw_task(
           ^^^^^^^^^^^^^^
  File "/home/airflow/.local/lib/python3.12/site-packages/airflow/models/taskinstance.py", line 273, in _run_raw_task
    TaskInstance._execute_task_with_callbacks(
  File "/home/airflow/.local/lib/python3.12/site-packages/airflow/models/taskinstance.py", line 3159, in _execute_task_with_callbacks
    result = self._execute_task(context, task_orig)
             ^^^^^^^^^^^^^^^^^^^^^^^^^^^^^^^^^^^^^^
  File "/home/airflow/.local/lib/python3.12/site-packages/airflow/models/taskinstance.py", line 3183, in _execute_task
    return _execute_task(self, context, task_orig)
           ^^^^^^^^^^^^^^^^^^^^^^^^^^^^^^^^^^^^^^^
  File "/home/airflow/.local/lib/python3.12/site-packages/airflow/models/taskinstance.py", line 767, in _execute_task
    result = _execute_callable(context=context, **execute_callable_kwargs)
             ^^^^^^^^^^^^^^^^^^^^^^^^^^^^^^^^^^^^^^^^^^^^^^^^^^^^^^^^^^^^^
  File "/home/airflow/.local/lib/python3.12/site-packages/airflow/models/taskinstance.py", line 733, in _execute_callable
    return ExecutionCallableRunner(
           ^^^^^^^^^^^^^^^^^^^^^^^^
  File "/home/airflow/.local/lib/python3.12/site-packages/airflow/utils/operator_helpers.py", line 252, in run
    return self.func(*args, **kwargs)
           ^^^^^^^^^^^^^^^^^^^^^^^^^^
  File "/home/airflow/.local/lib/python3.12/site-packages/airflow/models/baseoperator.py", line 422, in wrapper
    return func(self, *args, **kwargs)
           ^^^^^^^^^^^^^^^^^^^^^^^^^^^
  File "/home/airflow/.local/lib/python3.12/site-packages/airflow/operators/python.py", line 238, in execute
    return_value = self.execute_callable()
                   ^^^^^^^^^^^^^^^^^^^^^^^
  File "/home/airflow/.local/lib/python3.12/site-packages/airflow/operators/python.py", line 256, in execute_callable
    return runner.run(*self.op_args, **self.op_kwargs)
           ^^^^^^^^^^^^^^^^^^^^^^^^^^^^^^^^^^^^^^^^^^^
  File "/home/airflow/.local/lib/python3.12/site-packages/airflow/utils/operator_helpers.py", line 252, in run
    return self.func(*args, **kwargs)
           ^^^^^^^^^^^^^^^^^^^^^^^^^^
  File "/opt/airflow/dags/Incident_Report_Generation.py", line 187, in generar_reporte
    cursor.execute("SELECT switch_name, cliente_name FROM switches_y_clientes")
  File "/home/airflow/.local/lib/python3.12/site-packages/MySQLdb/cursors.py", line 179, in execute
    res = self._query(mogrified_query)
          ^^^^^^^^^^^^^^^^^^^^^^^^^^^^
  File "/home/airflow/.local/lib/python3.12/site-packages/MySQLdb/cursors.py", line 330, in _query
    db.query(q)
  File "/home/airflow/.local/lib/python3.12/site-packages/MySQLdb/connections.py", line 265, in query
    _mysql.connection.query(self, query)
MySQLdb.OperationalError: (1054, "Unknown column 'cliente_name' in 'field list'")
[2025-02-08T07:58:34.246+0000] {local_task_job_runner.py:266} INFO - Task exited with return code 1
[2025-02-08T07:58:34.272+0000] {taskinstance.py:3895} INFO - 0 downstream tasks scheduled from follow-on schedule check
[2025-02-08T07:58:34.278+0000] {local_task_job_runner.py:245} INFO - ::endgroup::
