[2025-02-08T08:05:03.194+0000] {local_task_job_runner.py:123} INFO - ::group::Pre task execution logs
[2025-02-08T08:05:03.468+0000] {taskinstance.py:2613} INFO - Dependencies all met for dep_context=non-requeueable deps ti=<TaskInstance: Incident_Report_Generation.generar_reporte manual__2025-02-08T08:04:34.869715+00:00 [queued]>
[2025-02-08T08:05:03.483+0000] {taskinstance.py:2613} INFO - Dependencies all met for dep_context=requeueable deps ti=<TaskInstance: Incident_Report_Generation.generar_reporte manual__2025-02-08T08:04:34.869715+00:00 [queued]>
[2025-02-08T08:05:03.484+0000] {taskinstance.py:2866} INFO - Starting attempt 1 of 2
[2025-02-08T08:05:03.510+0000] {taskinstance.py:2889} INFO - Executing <Task(PythonOperator): generar_reporte> on 2025-02-08 08:04:34.869715+00:00
[2025-02-08T08:05:03.521+0000] {warnings.py:112} WARNING - /home/***/.local/lib/python3.12/site-packages/***/task/task_runner/standard_task_runner.py:70: DeprecationWarning: This process (pid=5358) is multi-threaded, use of fork() may lead to deadlocks in the child.
  pid = os.fork()

[2025-02-08T08:05:03.526+0000] {standard_task_runner.py:72} INFO - Started process 5360 to run task
[2025-02-08T08:05:03.526+0000] {standard_task_runner.py:104} INFO - Running: ['***', 'tasks', 'run', 'Incident_Report_Generation', 'generar_reporte', 'manual__2025-02-08T08:04:34.869715+00:00', '--job-id', '255', '--raw', '--subdir', 'DAGS_FOLDER/Incident_Report_Generation.py', '--cfg-path', '/tmp/tmpq9aklj3q']
[2025-02-08T08:05:03.528+0000] {standard_task_runner.py:105} INFO - Job 255: Subtask generar_reporte
[2025-02-08T08:05:03.605+0000] {task_command.py:467} INFO - Running <TaskInstance: Incident_Report_Generation.generar_reporte manual__2025-02-08T08:04:34.869715+00:00 [running]> on host 0b0ecc2e9e80
[2025-02-08T08:05:03.736+0000] {taskinstance.py:3132} INFO - Exporting env vars: AIRFLOW_CTX_DAG_OWNER='***' AIRFLOW_CTX_DAG_ID='Incident_Report_Generation' AIRFLOW_CTX_TASK_ID='generar_reporte' AIRFLOW_CTX_EXECUTION_DATE='2025-02-08T08:04:34.869715+00:00' AIRFLOW_CTX_TRY_NUMBER='1' AIRFLOW_CTX_DAG_RUN_ID='manual__2025-02-08T08:04:34.869715+00:00'
[2025-02-08T08:05:03.738+0000] {logging_mixin.py:190} INFO - Task instance is in running state
[2025-02-08T08:05:03.739+0000] {logging_mixin.py:190} INFO -  Previous state of the Task instance: queued
[2025-02-08T08:05:03.742+0000] {logging_mixin.py:190} INFO - Current task name:generar_reporte state:running start_date:2025-02-08 08:05:03.469644+00:00
[2025-02-08T08:05:03.745+0000] {logging_mixin.py:190} INFO - Dag name:Incident_Report_Generation and current dag run status:running
[2025-02-08T08:05:03.746+0000] {taskinstance.py:731} INFO - ::endgroup::
[2025-02-08T08:05:03.821+0000] {base.py:84} INFO - Retrieving connection 'mysql_default1'
[2025-02-08T08:05:03.988+0000] {taskinstance.py:3311} ERROR - Task failed with exception
Traceback (most recent call last):
  File "/home/airflow/.local/lib/python3.12/site-packages/airflow/models/taskinstance.py", line 767, in _execute_task
    result = _execute_callable(context=context, **execute_callable_kwargs)
             ^^^^^^^^^^^^^^^^^^^^^^^^^^^^^^^^^^^^^^^^^^^^^^^^^^^^^^^^^^^^^
  File "/home/airflow/.local/lib/python3.12/site-packages/airflow/models/taskinstance.py", line 733, in _execute_callable
    return ExecutionCallableRunner(
           ^^^^^^^^^^^^^^^^^^^^^^^^
  File "/home/airflow/.local/lib/python3.12/site-packages/airflow/utils/operator_helpers.py", line 252, in run
    return self.func(*args, **kwargs)
           ^^^^^^^^^^^^^^^^^^^^^^^^^^
  File "/home/airflow/.local/lib/python3.12/site-packages/airflow/models/baseoperator.py", line 422, in wrapper
    return func(self, *args, **kwargs)
           ^^^^^^^^^^^^^^^^^^^^^^^^^^^
  File "/home/airflow/.local/lib/python3.12/site-packages/airflow/operators/python.py", line 238, in execute
    return_value = self.execute_callable()
                   ^^^^^^^^^^^^^^^^^^^^^^^
  File "/home/airflow/.local/lib/python3.12/site-packages/airflow/operators/python.py", line 256, in execute_callable
    return runner.run(*self.op_args, **self.op_kwargs)
           ^^^^^^^^^^^^^^^^^^^^^^^^^^^^^^^^^^^^^^^^^^^
  File "/home/airflow/.local/lib/python3.12/site-packages/airflow/utils/operator_helpers.py", line 252, in run
    return self.func(*args, **kwargs)
           ^^^^^^^^^^^^^^^^^^^^^^^^^^
  File "/opt/airflow/dags/Incident_Report_Generation.py", line 216, in generar_reporte
    restart_logs = restart_data["top_3_equipos"]
                   ~~~~~~~~~~~~^^^^^^^^^^^^^^^^^
KeyError: 'top_3_equipos'
[2025-02-08T08:05:04.064+0000] {logging_mixin.py:190} INFO - Task instance in failure state
[2025-02-08T08:05:04.072+0000] {logging_mixin.py:190} INFO - Task start:2025-02-08 08:05:03.469644+00:00 end:2025-02-08 08:05:04.060870+00:00 duration:0.591226
[2025-02-08T08:05:04.104+0000] {logging_mixin.py:190} INFO - Task:<Task(PythonOperator): generar_reporte> dag:<DAG: Incident_Report_Generation> dagrun:<DagRun Incident_Report_Generation @ 2025-02-08 08:04:34.869715+00:00: manual__2025-02-08T08:04:34.869715+00:00, state:running, queued_at: 2025-02-08 08:04:36.042169+00:00. externally triggered: True>
[2025-02-08T08:05:04.116+0000] {logging_mixin.py:190} INFO - Failure caused by 'top_3_equipos'
[2025-02-08T08:05:04.122+0000] {taskinstance.py:1225} INFO - Marking task as UP_FOR_RETRY. dag_id=Incident_Report_Generation, task_id=generar_reporte, run_id=manual__2025-02-08T08:04:34.869715+00:00, execution_date=20250208T080434, start_date=20250208T080503, end_date=20250208T080504
[2025-02-08T08:05:04.218+0000] {taskinstance.py:340} INFO - ::group::Post task execution logs
[2025-02-08T08:05:04.223+0000] {standard_task_runner.py:124} ERROR - Failed to execute job 255 for task generar_reporte ('top_3_equipos'; 5360)
Traceback (most recent call last):
  File "/home/airflow/.local/lib/python3.12/site-packages/airflow/task/task_runner/standard_task_runner.py", line 117, in _start_by_fork
    ret = args.func(args, dag=self.dag)
          ^^^^^^^^^^^^^^^^^^^^^^^^^^^^^
  File "/home/airflow/.local/lib/python3.12/site-packages/airflow/cli/cli_config.py", line 49, in command
    return func(*args, **kwargs)
           ^^^^^^^^^^^^^^^^^^^^^
  File "/home/airflow/.local/lib/python3.12/site-packages/airflow/utils/cli.py", line 116, in wrapper
    return f(*args, **kwargs)
           ^^^^^^^^^^^^^^^^^^
  File "/home/airflow/.local/lib/python3.12/site-packages/airflow/cli/commands/task_command.py", line 483, in task_run
    task_return_code = _run_task_by_selected_method(args, _dag, ti)
                       ^^^^^^^^^^^^^^^^^^^^^^^^^^^^^^^^^^^^^^^^^^^^
  File "/home/airflow/.local/lib/python3.12/site-packages/airflow/cli/commands/task_command.py", line 256, in _run_task_by_selected_method
    return _run_raw_task(args, ti)
           ^^^^^^^^^^^^^^^^^^^^^^^
  File "/home/airflow/.local/lib/python3.12/site-packages/airflow/cli/commands/task_command.py", line 341, in _run_raw_task
    return ti._run_raw_task(
           ^^^^^^^^^^^^^^^^^
  File "/home/airflow/.local/lib/python3.12/site-packages/airflow/utils/session.py", line 97, in wrapper
    return func(*args, session=session, **kwargs)
           ^^^^^^^^^^^^^^^^^^^^^^^^^^^^^^^^^^^^^^
  File "/home/airflow/.local/lib/python3.12/site-packages/airflow/models/taskinstance.py", line 3005, in _run_raw_task
    return _run_raw_task(
           ^^^^^^^^^^^^^^
  File "/home/airflow/.local/lib/python3.12/site-packages/airflow/models/taskinstance.py", line 273, in _run_raw_task
    TaskInstance._execute_task_with_callbacks(
  File "/home/airflow/.local/lib/python3.12/site-packages/airflow/models/taskinstance.py", line 3159, in _execute_task_with_callbacks
    result = self._execute_task(context, task_orig)
             ^^^^^^^^^^^^^^^^^^^^^^^^^^^^^^^^^^^^^^
  File "/home/airflow/.local/lib/python3.12/site-packages/airflow/models/taskinstance.py", line 3183, in _execute_task
    return _execute_task(self, context, task_orig)
           ^^^^^^^^^^^^^^^^^^^^^^^^^^^^^^^^^^^^^^^
  File "/home/airflow/.local/lib/python3.12/site-packages/airflow/models/taskinstance.py", line 767, in _execute_task
    result = _execute_callable(context=context, **execute_callable_kwargs)
             ^^^^^^^^^^^^^^^^^^^^^^^^^^^^^^^^^^^^^^^^^^^^^^^^^^^^^^^^^^^^^
  File "/home/airflow/.local/lib/python3.12/site-packages/airflow/models/taskinstance.py", line 733, in _execute_callable
    return ExecutionCallableRunner(
           ^^^^^^^^^^^^^^^^^^^^^^^^
  File "/home/airflow/.local/lib/python3.12/site-packages/airflow/utils/operator_helpers.py", line 252, in run
    return self.func(*args, **kwargs)
           ^^^^^^^^^^^^^^^^^^^^^^^^^^
  File "/home/airflow/.local/lib/python3.12/site-packages/airflow/models/baseoperator.py", line 422, in wrapper
    return func(self, *args, **kwargs)
           ^^^^^^^^^^^^^^^^^^^^^^^^^^^
  File "/home/airflow/.local/lib/python3.12/site-packages/airflow/operators/python.py", line 238, in execute
    return_value = self.execute_callable()
                   ^^^^^^^^^^^^^^^^^^^^^^^
  File "/home/airflow/.local/lib/python3.12/site-packages/airflow/operators/python.py", line 256, in execute_callable
    return runner.run(*self.op_args, **self.op_kwargs)
           ^^^^^^^^^^^^^^^^^^^^^^^^^^^^^^^^^^^^^^^^^^^
  File "/home/airflow/.local/lib/python3.12/site-packages/airflow/utils/operator_helpers.py", line 252, in run
    return self.func(*args, **kwargs)
           ^^^^^^^^^^^^^^^^^^^^^^^^^^
  File "/opt/airflow/dags/Incident_Report_Generation.py", line 216, in generar_reporte
    restart_logs = restart_data["top_3_equipos"]
                   ~~~~~~~~~~~~^^^^^^^^^^^^^^^^^
KeyError: 'top_3_equipos'
[2025-02-08T08:05:04.333+0000] {local_task_job_runner.py:266} INFO - Task exited with return code 1
[2025-02-08T08:05:04.482+0000] {taskinstance.py:3895} INFO - 0 downstream tasks scheduled from follow-on schedule check
[2025-02-08T08:05:04.504+0000] {local_task_job_runner.py:245} INFO - ::endgroup::
