[2025-02-08T04:19:25.371+0000] {local_task_job_runner.py:123} INFO - ::group::Pre task execution logs
[2025-02-08T04:19:25.467+0000] {taskinstance.py:2613} INFO - Dependencies all met for dep_context=non-requeueable deps ti=<TaskInstance: Incident_Report_Generation.procesar_logs_up_down manual__2025-02-08T04:13:42.244884+00:00 [queued]>
[2025-02-08T04:19:25.490+0000] {taskinstance.py:2613} INFO - Dependencies all met for dep_context=requeueable deps ti=<TaskInstance: Incident_Report_Generation.procesar_logs_up_down manual__2025-02-08T04:13:42.244884+00:00 [queued]>
[2025-02-08T04:19:25.491+0000] {taskinstance.py:2866} INFO - Starting attempt 2 of 2
[2025-02-08T04:19:25.550+0000] {taskinstance.py:2889} INFO - Executing <Task(PythonOperator): procesar_logs_up_down> on 2025-02-08 04:13:42.244884+00:00
[2025-02-08T04:19:25.618+0000] {warnings.py:112} WARNING - /home/***/.local/lib/python3.12/site-packages/***/task/task_runner/standard_task_runner.py:70: DeprecationWarning: This process (pid=2214) is multi-threaded, use of fork() may lead to deadlocks in the child.
  pid = os.fork()

[2025-02-08T04:19:25.638+0000] {standard_task_runner.py:72} INFO - Started process 2219 to run task
[2025-02-08T04:19:25.737+0000] {standard_task_runner.py:104} INFO - Running: ['***', 'tasks', 'run', 'Incident_Report_Generation', 'procesar_logs_up_down', 'manual__2025-02-08T04:13:42.244884+00:00', '--job-id', '112', '--raw', '--subdir', 'DAGS_FOLDER/Incident_Report_Generation.py', '--cfg-path', '/tmp/tmp5ftfdvxy']
[2025-02-08T04:19:25.739+0000] {standard_task_runner.py:105} INFO - Job 112: Subtask procesar_logs_up_down
[2025-02-08T04:19:27.110+0000] {task_command.py:467} INFO - Running <TaskInstance: Incident_Report_Generation.procesar_logs_up_down manual__2025-02-08T04:13:42.244884+00:00 [running]> on host 0b0ecc2e9e80
[2025-02-08T04:19:27.766+0000] {taskinstance.py:3132} INFO - Exporting env vars: AIRFLOW_CTX_DAG_OWNER='***' AIRFLOW_CTX_DAG_ID='Incident_Report_Generation' AIRFLOW_CTX_TASK_ID='procesar_logs_up_down' AIRFLOW_CTX_EXECUTION_DATE='2025-02-08T04:13:42.244884+00:00' AIRFLOW_CTX_TRY_NUMBER='2' AIRFLOW_CTX_DAG_RUN_ID='manual__2025-02-08T04:13:42.244884+00:00'
[2025-02-08T04:19:27.769+0000] {logging_mixin.py:190} INFO - Task instance is in running state
[2025-02-08T04:19:27.771+0000] {logging_mixin.py:190} INFO -  Previous state of the Task instance: queued
[2025-02-08T04:19:27.772+0000] {logging_mixin.py:190} INFO - Current task name:procesar_logs_up_down state:running start_date:2025-02-08 04:19:25.468998+00:00
[2025-02-08T04:19:27.773+0000] {logging_mixin.py:190} INFO - Dag name:Incident_Report_Generation and current dag run status:running
[2025-02-08T04:19:27.774+0000] {taskinstance.py:731} INFO - ::endgroup::
[2025-02-08T04:19:29.155+0000] {taskinstance.py:3311} ERROR - Task failed with exception
Traceback (most recent call last):
  File "/home/airflow/.local/lib/python3.12/site-packages/airflow/models/taskinstance.py", line 767, in _execute_task
    result = _execute_callable(context=context, **execute_callable_kwargs)
             ^^^^^^^^^^^^^^^^^^^^^^^^^^^^^^^^^^^^^^^^^^^^^^^^^^^^^^^^^^^^^
  File "/home/airflow/.local/lib/python3.12/site-packages/airflow/models/taskinstance.py", line 733, in _execute_callable
    return ExecutionCallableRunner(
           ^^^^^^^^^^^^^^^^^^^^^^^^
  File "/home/airflow/.local/lib/python3.12/site-packages/airflow/utils/operator_helpers.py", line 252, in run
    return self.func(*args, **kwargs)
           ^^^^^^^^^^^^^^^^^^^^^^^^^^
  File "/home/airflow/.local/lib/python3.12/site-packages/airflow/models/baseoperator.py", line 422, in wrapper
    return func(self, *args, **kwargs)
           ^^^^^^^^^^^^^^^^^^^^^^^^^^^
  File "/home/airflow/.local/lib/python3.12/site-packages/airflow/operators/python.py", line 238, in execute
    return_value = self.execute_callable()
                   ^^^^^^^^^^^^^^^^^^^^^^^
  File "/home/airflow/.local/lib/python3.12/site-packages/airflow/operators/python.py", line 256, in execute_callable
    return runner.run(*self.op_args, **self.op_kwargs)
           ^^^^^^^^^^^^^^^^^^^^^^^^^^^^^^^^^^^^^^^^^^^
  File "/home/airflow/.local/lib/python3.12/site-packages/airflow/utils/operator_helpers.py", line 252, in run
    return self.func(*args, **kwargs)
           ^^^^^^^^^^^^^^^^^^^^^^^^^^
  File "/opt/airflow/dags/Incident_Report_Generation.py", line 92, in procesar_logs_up_down
    interface_changes = [(log["device"], "0.0.0.0", log["timestamp"], log["message"]) for log in logs if "up" in log["message"] or "down" in log["message"]]
                                                                                                                 ~~~^^^^^^^^^^^
TypeError: tuple indices must be integers or slices, not str
[2025-02-08T04:19:29.194+0000] {logging_mixin.py:190} INFO - Task instance in failure state
[2025-02-08T04:19:29.205+0000] {logging_mixin.py:190} INFO - Task start:2025-02-08 04:19:25.468998+00:00 end:2025-02-08 04:19:29.193805+00:00 duration:3.724807
[2025-02-08T04:19:29.216+0000] {logging_mixin.py:190} INFO - Task:<Task(PythonOperator): procesar_logs_up_down> dag:<DAG: Incident_Report_Generation> dagrun:<DagRun Incident_Report_Generation @ 2025-02-08 04:13:42.244884+00:00: manual__2025-02-08T04:13:42.244884+00:00, state:running, queued_at: 2025-02-08 04:13:42.614962+00:00. externally triggered: True>
[2025-02-08T04:19:29.220+0000] {logging_mixin.py:190} INFO - Failure caused by tuple indices must be integers or slices, not str
[2025-02-08T04:19:29.236+0000] {taskinstance.py:1225} INFO - Marking task as FAILED. dag_id=Incident_Report_Generation, task_id=procesar_logs_up_down, run_id=manual__2025-02-08T04:13:42.244884+00:00, execution_date=20250208T041342, start_date=20250208T041925, end_date=20250208T041929
[2025-02-08T04:19:29.324+0000] {taskinstance.py:340} INFO - ::group::Post task execution logs
[2025-02-08T04:19:29.325+0000] {standard_task_runner.py:124} ERROR - Failed to execute job 112 for task procesar_logs_up_down (tuple indices must be integers or slices, not str; 2219)
Traceback (most recent call last):
  File "/home/airflow/.local/lib/python3.12/site-packages/airflow/task/task_runner/standard_task_runner.py", line 117, in _start_by_fork
    ret = args.func(args, dag=self.dag)
          ^^^^^^^^^^^^^^^^^^^^^^^^^^^^^
  File "/home/airflow/.local/lib/python3.12/site-packages/airflow/cli/cli_config.py", line 49, in command
    return func(*args, **kwargs)
           ^^^^^^^^^^^^^^^^^^^^^
  File "/home/airflow/.local/lib/python3.12/site-packages/airflow/utils/cli.py", line 116, in wrapper
    return f(*args, **kwargs)
           ^^^^^^^^^^^^^^^^^^
  File "/home/airflow/.local/lib/python3.12/site-packages/airflow/cli/commands/task_command.py", line 483, in task_run
    task_return_code = _run_task_by_selected_method(args, _dag, ti)
                       ^^^^^^^^^^^^^^^^^^^^^^^^^^^^^^^^^^^^^^^^^^^^
  File "/home/airflow/.local/lib/python3.12/site-packages/airflow/cli/commands/task_command.py", line 256, in _run_task_by_selected_method
    return _run_raw_task(args, ti)
           ^^^^^^^^^^^^^^^^^^^^^^^
  File "/home/airflow/.local/lib/python3.12/site-packages/airflow/cli/commands/task_command.py", line 341, in _run_raw_task
    return ti._run_raw_task(
           ^^^^^^^^^^^^^^^^^
  File "/home/airflow/.local/lib/python3.12/site-packages/airflow/utils/session.py", line 97, in wrapper
    return func(*args, session=session, **kwargs)
           ^^^^^^^^^^^^^^^^^^^^^^^^^^^^^^^^^^^^^^
  File "/home/airflow/.local/lib/python3.12/site-packages/airflow/models/taskinstance.py", line 3005, in _run_raw_task
    return _run_raw_task(
           ^^^^^^^^^^^^^^
  File "/home/airflow/.local/lib/python3.12/site-packages/airflow/models/taskinstance.py", line 273, in _run_raw_task
    TaskInstance._execute_task_with_callbacks(
  File "/home/airflow/.local/lib/python3.12/site-packages/airflow/models/taskinstance.py", line 3159, in _execute_task_with_callbacks
    result = self._execute_task(context, task_orig)
             ^^^^^^^^^^^^^^^^^^^^^^^^^^^^^^^^^^^^^^
  File "/home/airflow/.local/lib/python3.12/site-packages/airflow/models/taskinstance.py", line 3183, in _execute_task
    return _execute_task(self, context, task_orig)
           ^^^^^^^^^^^^^^^^^^^^^^^^^^^^^^^^^^^^^^^
  File "/home/airflow/.local/lib/python3.12/site-packages/airflow/models/taskinstance.py", line 767, in _execute_task
    result = _execute_callable(context=context, **execute_callable_kwargs)
             ^^^^^^^^^^^^^^^^^^^^^^^^^^^^^^^^^^^^^^^^^^^^^^^^^^^^^^^^^^^^^
  File "/home/airflow/.local/lib/python3.12/site-packages/airflow/models/taskinstance.py", line 733, in _execute_callable
    return ExecutionCallableRunner(
           ^^^^^^^^^^^^^^^^^^^^^^^^
  File "/home/airflow/.local/lib/python3.12/site-packages/airflow/utils/operator_helpers.py", line 252, in run
    return self.func(*args, **kwargs)
           ^^^^^^^^^^^^^^^^^^^^^^^^^^
  File "/home/airflow/.local/lib/python3.12/site-packages/airflow/models/baseoperator.py", line 422, in wrapper
    return func(self, *args, **kwargs)
           ^^^^^^^^^^^^^^^^^^^^^^^^^^^
  File "/home/airflow/.local/lib/python3.12/site-packages/airflow/operators/python.py", line 238, in execute
    return_value = self.execute_callable()
                   ^^^^^^^^^^^^^^^^^^^^^^^
  File "/home/airflow/.local/lib/python3.12/site-packages/airflow/operators/python.py", line 256, in execute_callable
    return runner.run(*self.op_args, **self.op_kwargs)
           ^^^^^^^^^^^^^^^^^^^^^^^^^^^^^^^^^^^^^^^^^^^
  File "/home/airflow/.local/lib/python3.12/site-packages/airflow/utils/operator_helpers.py", line 252, in run
    return self.func(*args, **kwargs)
           ^^^^^^^^^^^^^^^^^^^^^^^^^^
  File "/opt/airflow/dags/Incident_Report_Generation.py", line 92, in procesar_logs_up_down
    interface_changes = [(log["device"], "0.0.0.0", log["timestamp"], log["message"]) for log in logs if "up" in log["message"] or "down" in log["message"]]
                                                                                                                 ~~~^^^^^^^^^^^
TypeError: tuple indices must be integers or slices, not str
[2025-02-08T04:19:29.484+0000] {local_task_job_runner.py:266} INFO - Task exited with return code 1
[2025-02-08T04:19:29.513+0000] {taskinstance.py:3895} INFO - 0 downstream tasks scheduled from follow-on schedule check
[2025-02-08T04:19:29.523+0000] {local_task_job_runner.py:245} INFO - ::endgroup::
