[2025-02-08T07:47:19.640+0000] {local_task_job_runner.py:123} INFO - ::group::Pre task execution logs
[2025-02-08T07:47:20.140+0000] {taskinstance.py:2613} INFO - Dependencies all met for dep_context=non-requeueable deps ti=<TaskInstance: Incident_Report_Generation.generar_reporte manual__2025-02-08T07:44:04.599881+00:00 [queued]>
[2025-02-08T07:47:20.173+0000] {taskinstance.py:2613} INFO - Dependencies all met for dep_context=requeueable deps ti=<TaskInstance: Incident_Report_Generation.generar_reporte manual__2025-02-08T07:44:04.599881+00:00 [queued]>
[2025-02-08T07:47:20.185+0000] {taskinstance.py:2866} INFO - Starting attempt 1 of 2
[2025-02-08T07:47:20.232+0000] {taskinstance.py:2889} INFO - Executing <Task(PythonOperator): generar_reporte> on 2025-02-08 07:44:04.599881+00:00
[2025-02-08T07:47:20.264+0000] {standard_task_runner.py:104} INFO - Running: ['***', 'tasks', 'run', 'Incident_Report_Generation', 'generar_reporte', 'manual__2025-02-08T07:44:04.599881+00:00', '--job-id', '236', '--raw', '--subdir', 'DAGS_FOLDER/Incident_Report_Generation.py', '--cfg-path', '/tmp/tmpl6rew6s7']
[2025-02-08T07:47:20.263+0000] {warnings.py:112} WARNING - /home/***/.local/lib/python3.12/site-packages/***/task/task_runner/standard_task_runner.py:70: DeprecationWarning: This process (pid=5082) is multi-threaded, use of fork() may lead to deadlocks in the child.
  pid = os.fork()

[2025-02-08T07:47:20.270+0000] {standard_task_runner.py:72} INFO - Started process 5084 to run task
[2025-02-08T07:47:20.269+0000] {standard_task_runner.py:105} INFO - Job 236: Subtask generar_reporte
[2025-02-08T07:47:20.405+0000] {task_command.py:467} INFO - Running <TaskInstance: Incident_Report_Generation.generar_reporte manual__2025-02-08T07:44:04.599881+00:00 [running]> on host 0b0ecc2e9e80
[2025-02-08T07:47:20.796+0000] {taskinstance.py:3132} INFO - Exporting env vars: AIRFLOW_CTX_DAG_OWNER='***' AIRFLOW_CTX_DAG_ID='Incident_Report_Generation' AIRFLOW_CTX_TASK_ID='generar_reporte' AIRFLOW_CTX_EXECUTION_DATE='2025-02-08T07:44:04.599881+00:00' AIRFLOW_CTX_TRY_NUMBER='1' AIRFLOW_CTX_DAG_RUN_ID='manual__2025-02-08T07:44:04.599881+00:00'
[2025-02-08T07:47:20.801+0000] {logging_mixin.py:190} INFO - Task instance is in running state
[2025-02-08T07:47:20.811+0000] {logging_mixin.py:190} INFO -  Previous state of the Task instance: queued
[2025-02-08T07:47:20.814+0000] {logging_mixin.py:190} INFO - Current task name:generar_reporte state:running start_date:2025-02-08 07:47:20.154968+00:00
[2025-02-08T07:47:20.830+0000] {logging_mixin.py:190} INFO - Dag name:Incident_Report_Generation and current dag run status:running
[2025-02-08T07:47:20.833+0000] {taskinstance.py:731} INFO - ::endgroup::
[2025-02-08T07:47:21.035+0000] {base.py:84} INFO - Retrieving connection 'mysql_default1'
[2025-02-08T07:47:22.118+0000] {taskinstance.py:3311} ERROR - Task failed with exception
Traceback (most recent call last):
  File "/home/airflow/.local/lib/python3.12/site-packages/airflow/models/taskinstance.py", line 767, in _execute_task
    result = _execute_callable(context=context, **execute_callable_kwargs)
             ^^^^^^^^^^^^^^^^^^^^^^^^^^^^^^^^^^^^^^^^^^^^^^^^^^^^^^^^^^^^^
  File "/home/airflow/.local/lib/python3.12/site-packages/airflow/models/taskinstance.py", line 733, in _execute_callable
    return ExecutionCallableRunner(
           ^^^^^^^^^^^^^^^^^^^^^^^^
  File "/home/airflow/.local/lib/python3.12/site-packages/airflow/utils/operator_helpers.py", line 252, in run
    return self.func(*args, **kwargs)
           ^^^^^^^^^^^^^^^^^^^^^^^^^^
  File "/home/airflow/.local/lib/python3.12/site-packages/airflow/models/baseoperator.py", line 422, in wrapper
    return func(self, *args, **kwargs)
           ^^^^^^^^^^^^^^^^^^^^^^^^^^^
  File "/home/airflow/.local/lib/python3.12/site-packages/airflow/operators/python.py", line 238, in execute
    return_value = self.execute_callable()
                   ^^^^^^^^^^^^^^^^^^^^^^^
  File "/home/airflow/.local/lib/python3.12/site-packages/airflow/operators/python.py", line 256, in execute_callable
    return runner.run(*self.op_args, **self.op_kwargs)
           ^^^^^^^^^^^^^^^^^^^^^^^^^^^^^^^^^^^^^^^^^^^
  File "/home/airflow/.local/lib/python3.12/site-packages/airflow/utils/operator_helpers.py", line 252, in run
    return self.func(*args, **kwargs)
           ^^^^^^^^^^^^^^^^^^^^^^^^^^
  File "/opt/airflow/dags/Incident_Report_Generation.py", line 184, in generar_reporte
    cursor, connection = connect_template_db("mysql_default1")
                         ^^^^^^^^^^^^^^^^^^^^^^^^^^^^^^^^^^^^^
  File "/opt/airflow/dags/Incident_Report_Generation.py", line 19, in connect_template_db
    connection = mysql_hook.get_conn()
                 ^^^^^^^^^^^^^^^^^^^^^
  File "/home/airflow/.local/lib/python3.12/site-packages/airflow/providers/mysql/hooks/mysql.py", line 224, in get_conn
    return MySQLdb.connect(**conn_config)
           ^^^^^^^^^^^^^^^^^^^^^^^^^^^^^^
  File "/home/airflow/.local/lib/python3.12/site-packages/MySQLdb/__init__.py", line 121, in Connect
    return Connection(*args, **kwargs)
           ^^^^^^^^^^^^^^^^^^^^^^^^^^^
  File "/home/airflow/.local/lib/python3.12/site-packages/MySQLdb/connections.py", line 199, in __init__
    super().__init__(*args, **kwargs2)
MySQLdb.OperationalError: (1045, "Access denied for user 'user'@'172.27.0.3' (using password: NO)")
[2025-02-08T07:47:22.375+0000] {logging_mixin.py:190} INFO - Task instance in failure state
[2025-02-08T07:47:22.379+0000] {logging_mixin.py:190} INFO - Task start:2025-02-08 07:47:20.154968+00:00 end:2025-02-08 07:47:22.374635+00:00 duration:2.219667
[2025-02-08T07:47:22.382+0000] {logging_mixin.py:190} INFO - Task:<Task(PythonOperator): generar_reporte> dag:<DAG: Incident_Report_Generation> dagrun:<DagRun Incident_Report_Generation @ 2025-02-08 07:44:04.599881+00:00: manual__2025-02-08T07:44:04.599881+00:00, state:running, queued_at: 2025-02-08 07:44:05.044031+00:00. externally triggered: True>
[2025-02-08T07:47:22.387+0000] {logging_mixin.py:190} INFO - Failure caused by (1045, "Access denied for user 'user'@'172.27.0.3' (using password: NO)")
[2025-02-08T07:47:22.388+0000] {taskinstance.py:1225} INFO - Marking task as UP_FOR_RETRY. dag_id=Incident_Report_Generation, task_id=generar_reporte, run_id=manual__2025-02-08T07:44:04.599881+00:00, execution_date=20250208T074404, start_date=20250208T074720, end_date=20250208T074722
[2025-02-08T07:47:22.551+0000] {taskinstance.py:340} INFO - ::group::Post task execution logs
[2025-02-08T07:47:22.552+0000] {standard_task_runner.py:124} ERROR - Failed to execute job 236 for task generar_reporte ((1045, "Access denied for user 'user'@'172.27.0.3' (using password: NO)"); 5084)
Traceback (most recent call last):
  File "/home/airflow/.local/lib/python3.12/site-packages/airflow/task/task_runner/standard_task_runner.py", line 117, in _start_by_fork
    ret = args.func(args, dag=self.dag)
          ^^^^^^^^^^^^^^^^^^^^^^^^^^^^^
  File "/home/airflow/.local/lib/python3.12/site-packages/airflow/cli/cli_config.py", line 49, in command
    return func(*args, **kwargs)
           ^^^^^^^^^^^^^^^^^^^^^
  File "/home/airflow/.local/lib/python3.12/site-packages/airflow/utils/cli.py", line 116, in wrapper
    return f(*args, **kwargs)
           ^^^^^^^^^^^^^^^^^^
  File "/home/airflow/.local/lib/python3.12/site-packages/airflow/cli/commands/task_command.py", line 483, in task_run
    task_return_code = _run_task_by_selected_method(args, _dag, ti)
                       ^^^^^^^^^^^^^^^^^^^^^^^^^^^^^^^^^^^^^^^^^^^^
  File "/home/airflow/.local/lib/python3.12/site-packages/airflow/cli/commands/task_command.py", line 256, in _run_task_by_selected_method
    return _run_raw_task(args, ti)
           ^^^^^^^^^^^^^^^^^^^^^^^
  File "/home/airflow/.local/lib/python3.12/site-packages/airflow/cli/commands/task_command.py", line 341, in _run_raw_task
    return ti._run_raw_task(
           ^^^^^^^^^^^^^^^^^
  File "/home/airflow/.local/lib/python3.12/site-packages/airflow/utils/session.py", line 97, in wrapper
    return func(*args, session=session, **kwargs)
           ^^^^^^^^^^^^^^^^^^^^^^^^^^^^^^^^^^^^^^
  File "/home/airflow/.local/lib/python3.12/site-packages/airflow/models/taskinstance.py", line 3005, in _run_raw_task
    return _run_raw_task(
           ^^^^^^^^^^^^^^
  File "/home/airflow/.local/lib/python3.12/site-packages/airflow/models/taskinstance.py", line 273, in _run_raw_task
    TaskInstance._execute_task_with_callbacks(
  File "/home/airflow/.local/lib/python3.12/site-packages/airflow/models/taskinstance.py", line 3159, in _execute_task_with_callbacks
    result = self._execute_task(context, task_orig)
             ^^^^^^^^^^^^^^^^^^^^^^^^^^^^^^^^^^^^^^
  File "/home/airflow/.local/lib/python3.12/site-packages/airflow/models/taskinstance.py", line 3183, in _execute_task
    return _execute_task(self, context, task_orig)
           ^^^^^^^^^^^^^^^^^^^^^^^^^^^^^^^^^^^^^^^
  File "/home/airflow/.local/lib/python3.12/site-packages/airflow/models/taskinstance.py", line 767, in _execute_task
    result = _execute_callable(context=context, **execute_callable_kwargs)
             ^^^^^^^^^^^^^^^^^^^^^^^^^^^^^^^^^^^^^^^^^^^^^^^^^^^^^^^^^^^^^
  File "/home/airflow/.local/lib/python3.12/site-packages/airflow/models/taskinstance.py", line 733, in _execute_callable
    return ExecutionCallableRunner(
           ^^^^^^^^^^^^^^^^^^^^^^^^
  File "/home/airflow/.local/lib/python3.12/site-packages/airflow/utils/operator_helpers.py", line 252, in run
    return self.func(*args, **kwargs)
           ^^^^^^^^^^^^^^^^^^^^^^^^^^
  File "/home/airflow/.local/lib/python3.12/site-packages/airflow/models/baseoperator.py", line 422, in wrapper
    return func(self, *args, **kwargs)
           ^^^^^^^^^^^^^^^^^^^^^^^^^^^
  File "/home/airflow/.local/lib/python3.12/site-packages/airflow/operators/python.py", line 238, in execute
    return_value = self.execute_callable()
                   ^^^^^^^^^^^^^^^^^^^^^^^
  File "/home/airflow/.local/lib/python3.12/site-packages/airflow/operators/python.py", line 256, in execute_callable
    return runner.run(*self.op_args, **self.op_kwargs)
           ^^^^^^^^^^^^^^^^^^^^^^^^^^^^^^^^^^^^^^^^^^^
  File "/home/airflow/.local/lib/python3.12/site-packages/airflow/utils/operator_helpers.py", line 252, in run
    return self.func(*args, **kwargs)
           ^^^^^^^^^^^^^^^^^^^^^^^^^^
  File "/opt/airflow/dags/Incident_Report_Generation.py", line 184, in generar_reporte
    cursor, connection = connect_template_db("mysql_default1")
                         ^^^^^^^^^^^^^^^^^^^^^^^^^^^^^^^^^^^^^
  File "/opt/airflow/dags/Incident_Report_Generation.py", line 19, in connect_template_db
    connection = mysql_hook.get_conn()
                 ^^^^^^^^^^^^^^^^^^^^^
  File "/home/airflow/.local/lib/python3.12/site-packages/airflow/providers/mysql/hooks/mysql.py", line 224, in get_conn
    return MySQLdb.connect(**conn_config)
           ^^^^^^^^^^^^^^^^^^^^^^^^^^^^^^
  File "/home/airflow/.local/lib/python3.12/site-packages/MySQLdb/__init__.py", line 121, in Connect
    return Connection(*args, **kwargs)
           ^^^^^^^^^^^^^^^^^^^^^^^^^^^
  File "/home/airflow/.local/lib/python3.12/site-packages/MySQLdb/connections.py", line 199, in __init__
    super().__init__(*args, **kwargs2)
MySQLdb.OperationalError: (1045, "Access denied for user 'user'@'172.27.0.3' (using password: NO)")
[2025-02-08T07:47:22.649+0000] {local_task_job_runner.py:266} INFO - Task exited with return code 1
[2025-02-08T07:47:22.792+0000] {taskinstance.py:3895} INFO - 0 downstream tasks scheduled from follow-on schedule check
[2025-02-08T07:47:22.831+0000] {local_task_job_runner.py:245} INFO - ::endgroup::
